Workbook

Sheet README
A1: OSVX 통합 재무모델 (Agent S)
A3: 작성일 | B3: 2026-08-11
A4: 작성자 | B4: Agent S — 통합 재무모델 & Go/No-Go 판정
A5: 대상 사업 | B5: LG화학 재조합 콜라겐(single+triple) + mTG 가교 Defined Organoid Matrix
A6: 통화 / 단위 | B6: 전 금액 USD. 물량은 **판매(sellable) L** 기준 — 생산 L = 판매 L / 0.836 (Agent V V-03 단위 통일)
A7: 환율 | B7: KRW 1,409.94 / USD, CNY 6.7474 / USD, JPY 157.54 / USD — Agent C [E-146] 단일 소스 승계
A8: 할인율(WACC) | B8: 8.66% = 자기자본 0.886×Ke 9.25% + 타인자본 0.114×Kd(세후) 4.06% (Rf 4.30% [E-800] / 한국 ERP 4.87% [E-801] / 무차입베타 0.93 [E-804] / 법인세 27.5% [E-805])
A9: 원가 함수 | B9: COGS(판매 mL) = 규모티어 고정비 ÷ (생산 L × 1000 × 0.836) + 티어 변동비. Agent E `cogs_model.py` 티어 파라미터 복제 (검증 완료)
A10: 침투율 | B10: 로지스틱 S-curve P(t) = L / (1 + exp(−k(t−t0))). L·k·t0 를 Agent D 의 switch_propensity·half_life 에서 유도. **선형 점유율 가정 없음**
A11: 시나리오 | B11: Bear / Base / Bull. 확률 가중 0.55 / 0.33 / 0.12 (Agent X §15.2 P(성공)=0.12 에서 유도)
A12: 스코프 | B12: A = 현 제품정의(오가노이드 매트릭스 단품) / B = 대안 스코프 옵션(b) 제품정의 확장(+비오가노이드 3D +콜라겐·젤라틴 바이오잉크)
A13: 반영 감사 | B13: Agent V V-01~V-26 (심각도 상 10건 전건) / Agent R 근거품질 FAIL 2항목 + 유통마진 69.0% 정정 / Agent X H1~H12·KC-1~KC-5
A14: 주의 (Agent R) | B14: ① 시장규모 근거품질 FAIL (T1 39.4%) ③ COGS·GM 근거품질 FAIL (T1 37.1%). 두 축의 수치는 방향성 지표로만 사용하고 단정 서술을 피할 것
... A18: 연계 산출물 | B18: docs/S_synthesis.md · model/finance_model.py · data/finance_output.csv · evidence/evidence_S.jsonl

Sheet Inputs
A1: # | B1: 구분 | C1: 파라미터 | D1: 값 | E1: 단위 | F1: 근거 [E-###] | G1: 비고
A2: 1 | B2: 할인율 | C2: 무위험이자율 Rf (한국 국고채 10년) | D2: 0.043 | E2: 비율 | F2: [E-800] | G2: 2026-08-11 실측 4.30%
A3: 2 | B3: 할인율 | C3: 한국 총 주식위험프리미엄 ERP | D3: 0.0487 | E3: 비율 | F3: [E-801] | G3: Damodaran 2026-01 (성숙시장 4.23% + 국가 0.64%)
A4: 3 | B4: 할인율 | C4: 무차입 베타 (산업) | D4: 0.93 | E4: 배 | F4: [E-804] | G4: Healthcare Products 0.83 / Drugs Biotech 1.03 평균
A5: 4 | B5: 할인율 | C5: 산업 D/E | D5: 0.129 | E5: 비율 | F5: [E-804] | G5: 12.79% · 13.04% 평균
A6: 5 | B6: 할인율 | C6: 법인세율 (한국 최고구간+지방세) | D6: 0.275 | E6: 비율 | F6: [E-805] | G6: 국세 25% × 1.1
A7: 6 | B7: 할인율 | C7: 회사채 스프레드 (LG화학 A3/BBB+) | D7: 0.013 | E7: 비율 | F7: [E-806] | G7: Moody's A3 / S&P BBB+
A8: 7 | B8: 원가 | C8: 종합수율 (RUO) | D8: 0.836 | E8: 비율 | F8: [E_cogs §6] | G8: 판매 L = 생산 L × 0.836
A9: 8 | B9: 원가 | C9: 티어1 고정비 (생산 1~9 L) | D9: 375000 | E9: USD/년 | F9: [E-428][E-434] | G9: 감가상각 35,000 포함
A10: 9 | B10: 원가 | C10: 티어10 고정비 (생산 10~99 L) | D10: 934215 | E10: USD/년 | F10: [E-428][E-434] | G10: 감가상각 154,215 포함, 5 FTE
A11: 10 | B11: 원가 | C11: 티어100 고정비 (생산 100~999 L) | D11: 1932700 | E11: USD/년 | F11: [E-428][E-434] | G11: 감가상각 342,700 포함, 11 FTE. E 의 파일럿 티어
A12: 11 | B12: 원가 | C12: 티어1000 고정비 (생산 ≥1000 L) | D12: 4082150 | E12: USD/년 | F12: [E-428][E-434] | G12: 감가상각 852,150 포함, 22 FTE
A13: 12 | B13: 원가 | C13: 티어100 판매 mL당 변동비 | D13: 0.7447 | E13: USD/mL | F13: [E-402][E-403][E-409] | G13: 원료 0.1606 + 배치 + 포장
... A40: 39 | B40: 대안스코프 | C40: TeloCol-6 커모디티 콜라겐 단가 | D40: 11.64 | E40: USD/mL | F40: [E-155] | G40: X: 비오가노이드 레그의 실질 가격 상한

Sheet Market
A1: 시나리오 | B1: 연도 | C1: 세그먼트 | D1: 지역 | E1: TAM USD | F1: TAM_addressable USD | G1: TAM_addressable L | H1: 침투율 P(t) | I1: SAM_adjusted USD | J1: SAM_adjusted L
A2: bear | B2: 2026 | C2: academic_ruo | D2: US | E2: 6646922 | F2: 4054622 | G2: 87.5532 | H2: 0.024316 | I2: =F2*H2 | J2: =G2*H2
A3: bear | B3: 2026 | C3: academic_ruo | D3: EU | E3: 7329269 | F3: 4470854 | G3: 96.541 | H3: 0.024316 | I3: =F3*H3 | J3: =G3*H3
A4: bear | B4: 2026 | C4: academic_ruo | D4: China | E4: 4192309 | F4: 2557308 | G4: 125.076 | H4: 0.024316 | I4: =F4*H4 | J4: =G4*H4
A5: bear | B5: 2026 | C5: academic_ruo | D5: Japan | E5: 1455118 | F5: 887622 | G5: 20.1756 | H5: 0.024316 | I5: =F5*H5 | J5: =G5*H5
A6: bear | B6: 2026 | C6: academic_ruo | D6: Korea | E6: 1236814 | F6: 754457 | G6: 18.1014 | H6: 0.024316 | I6: =F6*H6 | J6: =G6*H6
A7: bear | B7: 2026 | C7: academic_ruo | D7: RoW | E7: 4443370 | F7: 2710455 | G7: 73.16 | H7: 0.024316 | I7: =F7*H7 | J7: =G7*H7
A8: bear | B8: 2026 | C8: pharma_preclinical_nam | D8: US | E8: 2955612 | F8: 1625587 | G8: 41.2964 | H8: 0.033637 | I8: =F8*H8 | J8: =G8*H8
A9: bear | B9: 2026 | C9: pharma_preclinical_nam | D9: EU | E9: 1642007 | F9: 903104 | G9: 22.9425 | H9: 0.033637 | I9: =F9*H9 | J9: =G9*H9
A10: bear | B10: 2026 | C10: pharma_preclinical_nam | D10: China | E10: 434968 | F10: 239232 | G10: 13.7655 | H10: 0.033637 | I10: =F10*H10 | J10: =G10*H10
A11: bear | B11: 2026 | C11: pharma_preclinical_nam | D11: Japan | E11: 436774 | F11: 240226 | G11: 6.4239 | H11: 0.033637 | I11: =F11*H11 | J11: =G11*H11
A12: bear | B12: 2026 | C12: pharma_preclinical_nam | D12: Korea | E12: 177337 | F12: 97535 | G12: 2.7531 | H12: 0.033637 | I12: =F12*H12 | J12: =G12*H12
A13: bear | B13: 2026 | C13: pharma_preclinical_nam | D13: RoW | E13: 262721 | F13: 144497 | G13: 4.5885 | H13: 0.033637 | I13: =F13*H13 | J13: =G13*H13
... A901: bull | B901: 2035 | C901: regenerative_gmp | D901: RoW | E901: 0 | F901: 0 | G901: 0 | H901: 0.931283 | I901: =F901*H901 | J901: =G901*H901

Sheet Scenarios
A1: Bear / Base / Bull P&L — 스코프 A (현 제품정의). 물량·ASP 는 드라이버, 나머지는 엑셀 수식
A3: [BEAR] 스코프 A
A4: 항목 | B4: 2026 | C4: 2027 | D4: 2028 | E4: 2029 | F4: 2030 | G4: 2031 | H4: 2032 | I4: 2033 | J4: 2034 | K4: 2035
A5: 판매 물량 (L) | B5: 0.762 | C5: 1.018 | D5: 1.379 | E5: 1.89 | F5: 2.622 | G5: 3.428 | H5: 4.476 | I5: 5.826 | J5: 7.551 | K5: 9.73
A6: ASP (USD/mL) | B6: 19.39 | C6: 18.6144 | D6: 17.8698 | E6: 17.155 | F6: 16.4688 | G6: 15.8101 | H6: 15.1777 | I6: 14.5706 | J6: 13.9877 | K6: 13.4282
A7: 생산 물량 (L) | B7: =B5/Inputs!$D$8 | C7: =C5/Inputs!$D$8 | D7: =D5/Inputs!$D$8 | E7: =E5/Inputs!$D$8 | F7: =F5/Inputs!$D$8 | G7: =G5/Inputs!$D$8 | H7: =H5/Inputs!$D$8 | I7: =I5/Inputs!$D$8 | ... K7: =K5/Inputs!$D$8
A8: 매출 (USD) | B8: =B5*1000*B6 | C8: =C5*1000*C6 | D8: =D5*1000*D6 | E8: =E5*1000*E6 | F8: =F5*1000*F6 | G8: =G5*1000*G6 | H8: =H5*1000*H6 | I8: =I5*1000*I6 | ... K8: =K5*1000*K6
A9: 적용 고정비 (USD/년) | B9: 375000 | C9: 375000 | D9: 375000 | E9: 375000 | F9: 375000 | G9: 375000 | H9: 375000 | I9: 375000 | J9: 375000 | K9: 934215
A10: 적용 변동비 (USD/판매mL) | B10: 9.4851 | C10: 9.4851 | D10: 9.4851 | E10: 9.4851 | F10: 9.4851 | G10: 9.4851 | H10: 9.4851 | I10: 9.4851 | J10: 9.4851 | K10: 2.1247
A11: COGS (USD) | B11: =B9+B10*B5*1000 | C11: =C9+C10*C5*1000 | D11: =D9+D10*D5*1000 | E11: =E9+E10*E5*1000 | F11: =F9+F10*F5*1000 | G11: =G9+G10*G5*1000 | H11: =H9+H10*H5*1000 | I11: =I9+I10*I5*1000 | ... K11: =K9+K10*K5*1000
A12: Gross Profit (USD) | B12: =B8-B11 | C12: =C8-C11 | D12: =D8-D11 | E12: =E8-E11 | F12: =F8-F11 | G12: =G8-G11 | H12: =H8-H11 | I12: =I8-I11 | ... K12: =K8-K11
A13: GM % | B13: =IF(B8=0,0,B12/B8) | C13: =IF(C8=0,0,C12/C8) | D13: =IF(D8=0,0,D12/D8) | E13: =IF(E8=0,0,E12/E8) | F13: =IF(F8=0,0,F12/F8) | G13: =IF(G8=0,0,G12/G8) | H13: =IF(H8=0,0,H12/H8) | I13: =IF(I8=0,0,I12/I8) | ... K13: =IF(K8=0,0,K12/K8)
A14: SG&A (USD) | B14: 572343 | C14: 572343 | D14: 1144686 | E14: 1144686 | F14: 1144686 | G14: 1144686 | H14: 1144686 | I14: 1144686 | J14: 1144686 | K14: 1144686
A15: R&D (USD) | B15: 470000 | C15: 470000 | D15: 470000 | E15: 470000 | F15: 470000 | G15: 470000 | H15: 470000 | I15: 470000 | J15: 470000 | K15: 470000
A16: EBIT (USD) | B16: =B12-B14-B15 | C16: =C12-C14-C15 | D16: =D12-D14-D15 | E16: =E12-E14-E15 | F16: =F12-F14-F15 | G16: =G12-G14-G15 | H16: =H12-H14-H15 | I16: =I12-I14-I15 | ... K16: =K12-K14-K15
A17: 감가상각 (USD) | B17: 35000 | C17: 35000 | D17: 35000 | E17: 35000 | F17: 35000 | G17: 35000 | H17: 35000 | I17: 35000 | J17: 35000 | K17: 154215
A18: CAPEX (USD) | B18: 350000 | C18: 0 | D18: 0 | E18: 0 | F18: 0 | G18: 0 | H18: 0 | I18: 0 | J18: 1192150 | K18: 0
A19: 운전자본 증감 (USD) | B19: 3692 | C19: 1046 | D19: 1421 | E19: 1948 | F19: 2689 | G19: 2754 | H19: 3434 | I19: 4240 | J19: 5182 | K19: 6260
A20: 법인세 (USD) | B20: 0 | C20: 0 | D20: 0 | E20: 0 | F20: 0 | G20: 0 | H20: 0 | I20: 0 | J20: 0 | K20: 0
A21: FCF (USD) | B21: =B16-B20+B17-B18-B19 | C21: =C16-C20+C17-C18-C19 | D21: =D16-D20+D17-D18-D19 | E21: =E16-E20+E17-E18-E19 | F21: =F16-F20+F17-F18-F19 | G21: =G16-G20+G17-G18-G19 | H21: =H16-H20+H17-H18-H19 | I21: =I16-I20+I17-I18-I19 | ... K21: =K16-K20+K17-K18-K19
A22: 누적 FCF (USD) | B22: =B21 | C22: =B22+C21 | D22: =C22+D21 | E22: =D22+E21 | F22: =E22+F21 | G22: =F22+G21 | H22: =G22+H21 | I22: =H22+I21 | J22: =I22+J21 | K22: =J22+K21
A23: NPV (USD, 잔존가치 제외) | B23: =NPV(Gates!$B$2,C21:K21)+B21
A24: IRR (잔존가치 제외) | B24: =IFERROR(IRR(B21:K21),"미산출(부호변화 없음)")
A25: 누적 판매물량 (L) | B25: =SUM(B5:K5)
A27: [BASE] 스코프 A
A28: 항목 | B28: 2026 | C28: 2027 | D28: 2028 | E28: 2029 | F28: 2030 | G28: 2031 | H28: 2032 | I28: 2033 | J28: 2034 | K28: 2035
A29: 판매 물량 (L) | B29: 3.595 | C29: 5.436 | D29: 8.306 | E29: 12.786 | F29: 19.758 | G29: 27.234 | H29: 37.103 | I29: 49.851 | J29: 65.597 | K29: 84.86
A30: ASP (USD/mL) | B30: 24.93 | C30: 24.4314 | D30: 23.9428 | E30: 23.4639 | F30: 22.9946 | G30: 22.5347 | H30: 22.0841 | I30: 21.6424 | J30: 21.2095 | K30: 20.7853
A31: 생산 물량 (L) | B31: =B29/Inputs!$D$8 | C31: =C29/Inputs!$D$8 | D31: =D29/Inputs!$D$8 | E31: =E29/Inputs!$D$8 | F31: =F29/Inputs!$D$8 | G31: =G29/Inputs!$D$8 | H31: =H29/Inputs!$D$8 | I31: =I29/Inputs!$D$8 | ... K31: =K29/Inputs!$D$8
A32: 매출 (USD) | B32: =B29*1000*B30 | C32: =C29*1000*C30 | D32: =D29*1000*D30 | E32: =E29*1000*E30 | F32: =F29*1000*F30 | G32: =G29*1000*G30 | H32: =H29*1000*H30 | I32: =I29*1000*I30 | ... K32: =K29*1000*K30
A33: 적용 고정비 (USD/년) | B33: 375000 | C33: 375000 | D33: 375000 | E33: 934215 | F33: 934215 | G33: 934215 | H33: 934215 | I33: 934215 | J33: 934215 | K33: 1932700
A34: 적용 변동비 (USD/판매mL) | B34: 9.4851 | C34: 9.4851 | D34: 9.4851 | E34: 2.1247 | F34: 2.1247 | G34: 2.1247 | H34: 2.1247 | I34: 2.1247 | J34: 2.1247 | K34: 0.7447
A35: COGS (USD) | B35: =B33+B34*B29*1000 | C35: =C33+C34*C29*1000 | D35: =D33+D34*D29*1000 | E35: =E33+E34*E29*1000 | F35: =F33+F34*F29*1000 | G35: =G33+G34*G29*1000 | H35: =H33+H34*H29*1000 | I35: =I33+I34*I29*1000 | ... K35: =K33+K34*K29*1000
A36: Gross Profit (USD) | B36: =B32-B35 | C36: =C32-C35 | D36: =D32-D35 | E36: =E32-E35 | F36: =F32-F35 | G36: =G32-G35 | H36: =H32-H35 | I36: =I32-I35 | ... K36: =K32-K35
A37: GM % | B37: =IF(B32=0,0,B36/B32) | C37: =IF(C32=0,0,C36/C32) | D37: =IF(D32=0,0,D36/D32) | E37: =IF(E32=0,0,E36/E32) | F37: =IF(F32=0,0,F36/F32) | G37: =IF(G32=0,0,G36/G32) | H37: =IF(H32=0,0,H36/H32) | I37: =IF(I32=0,0,I36/I32) | ... K37: =IF(K32=0,0,K36/K32)
A38: SG&A (USD) | B38: 572343 | C38: 572343 | D38: 1144686 | E38: 1144686 | F38: 1144686 | G38: 1144686 | H38: 1144686 | I38: 1144686 | J38: 1144686 | K38: 1144686
A39: R&D (USD) | B39: 470000 | C39: 470000 | D39: 470000 | E39: 470000 | F39: 470000 | G39: 470000 | H39: 470000 | I39: 470000 | J39: 470000 | K39: 470000
A40: EBIT (USD) | B40: =B36-B38-B39 | C40: =C36-C38-C39 | D40: =D36-D38-D39 | E40: =E36-E38-E39 | F40: =F36-F38-F39 | G40: =G36-G38-G39 | H40: =H36-H38-H39 | I40: =I36-I38-I39 | ... K40: =K36-K38-K39
A41: 감가상각 (USD) | B41: 35000 | C41: 35000 | D41: 35000 | E41: 154215 | F41: 154215 | G41: 154215 | H41: 154215 | I41: 154215 | J41: 154215 | K41: 342700
A42: CAPEX (USD) | B42: 350000 | C42: 0 | D42: 1192150 | E42: 0 | F42: 0 | G42: 0 | H42: 0 | I42: 0 | J42: 1884850 | K42: 0
...

Sheet PnL_Base
A1: 스코프 A · Base 시나리오 10년 상세 P&L (2026~2035) — 파생 셀 전량 엑셀 수식
A3: 연도 | B3: 판매 L | C3: 생산 L | D3: ASP USD/mL | E3: 매출 USD | F3: 고정비 USD | G3: 변동비 USD/mL | H3: COGS USD | I3: Gross Profit | J3: GM % | K3: SG&A | L3: R&D | M3: EBIT | N3: 법인세 | O3: 감가상각 | P3: CAPEX | Q3: 누적 투자 | R3: 운전자본 증감 | S3: FCF | T3: 누적 FCF | U3: 할인계수 | V3: PV(FCF)
A4: 2026 | B4: 3.595 | C4: =B4/Inputs!$D$8 | D4: 24.93 | E4: =B4*1000*D4 | F4: 375000 | G4: 9.4851 | H4: =F4+G4*B4*1000 | I4: =E4-H4 | J4: =IF(E4=0,0,I4/E4) | K4: =MAX(Inputs!$D$31*E4,3*Inputs!$D$33) | L4: =MAX(Inputs!$D$32*E4,Inputs!$D$34) | M4: =I4-K4-L4 | N4: 0 | O4: 35000 | P4: 350000 | Q4: =SUM($P$4:P4) | R4: =0.25*E4 | S4: =M4-N4+O4-P4-R4 | T4: =S4 | U4: =1/(1+Gates!$B$2)^(A4-$A$4) | V4: =S4*U4
A5: 2027 | B5: 5.4363 | C5: =B5/Inputs!$D$8 | D5: 24.4314 | E5: =B5*1000*D5 | F5: 375000 | G5: 9.4851 | H5: =F5+G5*B5*1000 | I5: =E5-H5 | J5: =IF(E5=0,0,I5/E5) | K5: =MAX(Inputs!$D$31*E5,3*Inputs!$D$33) | L5: =MAX(Inputs!$D$32*E5,Inputs!$D$34) | M5: =I5-K5-L5 | N5: 0 | O5: 35000 | P5: 0 | Q5: =SUM($P$4:P5) | R5: =0.25*E5-0.25*E4 | S5: =M5-N5+O5-P5-R5 | T5: =T4+S5 | U5: =1/(1+Gates!$B$2)^(A5-$A$4) | V5: =S5*U5
A6: 2028 | B6: 8.3061 | C6: =B6/Inputs!$D$8 | D6: 23.9428 | E6: =B6*1000*D6 | F6: 375000 | G6: 9.4851 | H6: =F6+G6*B6*1000 | I6: =E6-H6 | J6: =IF(E6=0,0,I6/E6) | K6: =MAX(Inputs!$D$31*E6,6*Inputs!$D$33) | L6: =MAX(Inputs!$D$32*E6,Inputs!$D$34) | M6: =I6-K6-L6 | N6: 0 | O6: 35000 | P6: 1192150 | Q6: =SUM($P$4:P6) | R6: =0.25*E6-0.25*E5 | S6: =M6-N6+O6-P6-R6 | T6: =T5+S6 | U6: =1/(1+Gates!$B$2)^(A6-$A$4) | V6: =S6*U6
A7: 2029 | B7: 12.7864 | C7: =B7/Inputs!$D$8 | D7: 23.4639 | E7: =B7*1000*D7 | F7: 934215 | G7: 2.1247 | H7: =F7+G7*B7*1000 | I7: =E7-H7 | J7: =IF(E7=0,0,I7/E7) | K7: =MAX(Inputs!$D$31*E7,6*Inputs!$D$33) | L7: =MAX(Inputs!$D$32*E7,Inputs!$D$34) | M7: =I7-K7-L7 | N7: 0 | O7: 154215 | P7: 0 | Q7: =SUM($P$4:P7) | R7: =0.25*E7-0.25*E6 | S7: =M7-N7+O7-P7-R7 | T7: =T6+S7 | U7: =1/(1+Gates!$B$2)^(A7-$A$4) | V7: =S7*U7
A8: 2030 | B8: 19.7582 | C8: =B8/Inputs!$D$8 | D8: 22.9946 | E8: =B8*1000*D8 | F8: 934215 | G8: 2.1247 | H8: =F8+G8*B8*1000 | I8: =E8-H8 | J8: =IF(E8=0,0,I8/E8) | K8: =MAX(Inputs!$D$31*E8,6*Inputs!$D$33) | L8: =MAX(Inputs!$D$32*E8,Inputs!$D$34) | M8: =I8-K8-L8 | N8: 0 | O8: 154215 | P8: 0 | Q8: =SUM($P$4:P8) | R8: =0.25*E8-0.25*E7 | S8: =M8-N8+O8-P8-R8 | T8: =T7+S8 | U8: =1/(1+Gates!$B$2)^(A8-$A$4) | V8: =S8*U8
A9: 2031 | B9: 27.2342 | C9: =B9/Inputs!$D$8 | D9: 22.5347 | E9: =B9*1000*D9 | F9: 934215 | G9: 2.1247 | H9: =F9+G9*B9*1000 | I9: =E9-H9 | J9: =IF(E9=0,0,I9/E9) | K9: =MAX(Inputs!$D$31*E9,6*Inputs!$D$33) | L9: =MAX(Inputs!$D$32*E9,Inputs!$D$34) | M9: =I9-K9-L9 | N9: 0 | O9: 154215 | P9: 0 | Q9: =SUM($P$4:P9) | R9: =0.25*E9-0.25*E8 | S9: =M9-N9+O9-P9-R9 | T9: =T8+S9 | U9: =1/(1+Gates!$B$2)^(A9-$A$4) | V9: =S9*U9
A10: 2032 | B10: 37.103 | C10: =B10/Inputs!$D$8 | D10: 22.0841 | E10: =B10*1000*D10 | F10: 934215 | G10: 2.1247 | H10: =F10+G10*B10*1000 | I10: =E10-H10 | J10: =IF(E10=0,0,I10/E10) | K10: =MAX(Inputs!$D$31*E10,6*Inputs!$D$33) | L10: =MAX(Inputs!$D$32*E10,Inputs!$D$34) | M10: =I10-K10-L10 | N10: 0 | O10: 154215 | P10: 0 | Q10: =SUM($P$4:P10) | R10: =0.25*E10-0.25*E9 | S10: =M10-N10+O10-P10-R10 | T10: =T9+S10 | U10: =1/(1+Gates!$B$2)^(A10-$A$4) | V10: =S10*U10
A11: 2033 | B11: 49.8508 | C11: =B11/Inputs!$D$8 | D11: 21.6424 | E11: =B11*1000*D11 | F11: 934215 | G11: 2.1247 | H11: =F11+G11*B11*1000 | I11: =E11-H11 | J11: =IF(E11=0,0,I11/E11) | K11: =MAX(Inputs!$D$31*E11,6*Inputs!$D$33) | L11: =MAX(Inputs!$D$32*E11,Inputs!$D$34) | M11: =I11-K11-L11 | N11: 0 | O11: 154215 | P11: 0 | Q11: =SUM($P$4:P11) | R11: =0.25*E11-0.25*E10 | S11: =M11-N11+O11-P11-R11 | T11: =T10+S11 | U11: =1/(1+Gates!$B$2)^(A11-$A$4) | V11: =S11*U11
A12: 2034 | B12: 65.5973 | C12: =B12/Inputs!$D$8 | D12: 21.2095 | E12: =B12*1000*D12 | F12: 934215 | G12: 2.1247 | H12: =F12+G12*B12*1000 | I12: =E12-H12 | J12: =IF(E12=0,0,I12/E12) | K12: =MAX(Inputs!$D$31*E12,6*Inputs!$D$33) | L12: =MAX(Inputs!$D$32*E12,Inputs!$D$34) | M12: =I12-K12-L12 | N12: 0 | O12: 154215 | P12: 1884850 | Q12: =SUM($P$4:P12) | R12: =0.25*E12-0.25*E11 | S12: =M12-N12+O12-P12-R12 | T12: =T11+S12 | U12: =1/(1+Gates!$B$2)^(A12-$A$4) | V12: =S12*U12
A13: 2035 | B13: 84.8596 | C13: =B13/Inputs!$D$8 | D13: 20.7853 | E13: =B13*1000*D13 | F13: 1932700 | G13: 0.7447 | H13: =F13+G13*B13*1000 | I13: =E13-H13 | J13: =IF(E13=0,0,I13/E13) | K13: =MAX(Inputs!$D$31*E13,6*Inputs!$D$33) | L13: =MAX(Inputs!$D$32*E13,Inputs!$D$34) | M13: =I13-K13-L13 | N13: 0 | O13: 342700 | P13: 0 | Q13: =SUM($P$4:P13) | R13: =0.25*E13-0.25*E12 | S13: =M13-N13+O13-P13-R13 | T13: =T12+S13 | U13: =1/(1+Gates!$B$2)^(A13-$A$4) | V13: =S13*U13
A15: NPV (잔존가치 제외) | E15: =SUM(V4:V13)
A16: IRR | E16: =IFERROR(IRR(S4:S13),"미산출(전 기간 FCF 음수)")
A17: Payback (누적 FCF ≥ 0 최초 연도) | E17: =IFERROR(INDEX(A4:A13,MATCH(TRUE,INDEX(T4:T13>=0,0),0)),"미도달")
A18: BEP 연도 (EBIT ≥ 0 최초) | E18: =IFERROR(INDEX(A4:A13,MATCH(TRUE,INDEX(M4:M13>=0,0),0)),"미도달")
A19: BEP 누적물량 (판매 L) | E19: =IF(E18="미도달","미도달",SUM(B4:B13))
A20: 10년 누적 FCF | E20: =T13
A21: GM 60% 최초 통과 연도 | E21: =IFERROR(INDEX(A4:A13,MATCH(TRUE,INDEX(J4:J13>=0.6,0),0)),"미도달")

Sheet Sensitivity
A1: 토네이도 민감도 — 스코프 A Base, 각 변수 ±30% 시 NPV 변화 (USD)
A3: 순위 | B3: 변수 | C3: −30% NPV | D3: 기준 NPV | E3: +30% NPV | F3: −30% ΔNPV | G3: +30% ΔNPV | H3: 영향폭(절대) | I3: 근거
A4: 1 | B4: SG&A (FTE 단가·비율) | C4: -11968166 | D4: -14069419 | E4: -16170672 | F4: =C4-D4 | G4: =E4-D4 | H4: =ABS(E4-C4) | I4: [E-808][E-809]
A5: 2 | B5: 고정비 F (플랜트 규모) | C5: -12407818 | D5: -14069419 | E5: -15731019 | F5: =C5-D5 | G5: =E5-D5 | H5: =ABS(E5-C5) | I5: [E-428][E-434]
A6: 3 | B6: WACC | C6: -15500484 | D6: -14069419 | E6: -12854987 | F6: =C6-D6 | G6: =E6-D6 | H6: =ABS(E6-C6) | I6: [E-800][E-801][E-804]
A7: 4 | B7: ASP (판매단가) | C7: -15187106 | D7: -14069419 | E7: -12951732 | F7: =C7-D7 | G7: =E7-D7 | H7: =ABS(E7-C7) | I7: [E-802][E-803][E-807]
A8: 5 | B8: R&D 지출 | C8: -13071278 | D8: -14069419 | E8: -15067560 | F8: =C8-D8 | G8: =E8-D8 | H8: =ABS(E8-C8) | I8: [E-808]
A9: 6 | B9: CAPEX | C9: -13370545 | D9: -14069419 | E9: -14768293 | F9: =C9-D9 | G9: =E9-D9 | H9: =ABS(E9-C9) | I9: [E_cogs HANDOFF]
A10: 7 | B10: 변동비 v | C10: -13935460 | D10: -14069419 | E10: -14203378 | F10: =C10-D10 | G10: =E10-D10 | H10: =ABS(E10-C10) | I10: [E-402][E-403]
A11: 8 | B11: LG 점유율 | C11: -13738502 | D11: -14069419 | E11: -13918714 | F11: =C11-D11 | G11: =E11-D11 | H11: =ABS(E11-C11) | I11: [A-A21]
B13: Kill Criteria 발동 시 NPV
A14: # | B14: Kill Criterion | C14: 판정연도 | D14: 계속 시 NPV | E14: 중단 시 NPV | F14: 중단 옵션가치 | G14: 기준 대비 Δ | I14: 대응 반증
A15: 1 | B15: KC-1 mTG 삼중나선 가교 전환율 미달 (H7) | C15: 2026 | D15: -13912782 | E15: -1699224 | F15: =IF(ISNUMBER(D15),E15-D15,"—") | G15: =IF(ISNUMBER(D15),D15--14069419.0,"—") | I15: 점유율 12%→5% [X-A08] / 6개월 시점 중단
A16: 2 | B16: KC-2 라미닌 무첨가 형성효율 <34% (H2) | C16: 2027 | D16: 계속 불가 | E16: -2906557 | F16: =IF(ISNUMBER(D16),E16-D16,"—") | G16: =IF(ISNUMBER(D16),D16--14069419.0,"—") | I16: 라미닌 필수 시 COGS +110.96 USD/mL → 공헌이익 음수, 계속 불가
A17: 3 | B17: KC-3 Corning 354234 ≤ 27.00 USD/mL (H4) | C17: 2027 | D17: -14474261 | E17: -2906557 | F17: =IF(ISNUMBER(D17),E17-D17,"—") | G17: =IF(ISNUMBER(D17),D17--14069419.0,"—") | I17: ASP 24.93 → 22.22 USD/mL
A18: 4 | B18: KC-4 옵션(b) 2028 연환산 판매 < 289.9 L (H11) | C18: 2028 | D18: -12718425 | E18: -11828763 | F18: =IF(ISNUMBER(D18),E18-D18,"—") | G18: =IF(ISNUMBER(D18),D18--14069419.0,"—") | I18: 스코프 B 계속(잔존가치 제외) vs 2028년 말 중단
A19: 5 | B19: KC-5 전환서비스 랩당 >12,000 USD (H12) | C19: 2027 | D19: -13400895 | E19: -2906557 | F19: =IF(ISNUMBER(D19),E19-D19,"—") | G19: =IF(ISNUMBER(D19),D19--14069419.0,"—") | I19: 학술 RUO 세그먼트 제외 vs 중단

Sheet Gates
A1: DECISION_GATE 대조표
A2: WACC | B2: 0.0866 | C2: ← 이 셀을 바꾸면 Scenarios·PnL_Base 의 NPV 가 다시 계산된다
A4: 게이트 | B4: 임계값 | C4: Bear | D4: Base | E4: Bull | F4: 달성률(Base) | G4: 판정 | H4: 근거·비고
A5: SAM_2030 (USD) | B5: 150000000 | C5: 1626574.8 | D5: 5617438.9 | E5: 17337348 | F5: =D5/B5 | G5: =IF(MAX(C5:E5)>=B5,"PASS","FAIL") | H5: A 의 TAM_addressable × 로지스틱 침투율. Agent A 의 기하 누적모델(10.08 M)보다 보수적
A6: SOM_2030 (USD) | B6: 15000000 | C6: 43182.043 | D6: 454332 | E6: 3315028.4 | F6: =D6/B6 | G6: =IF(MAX(C6:E6)>=B6,"PASS","FAIL") | H6: LG 자신의 가격표 기준 (V-09). 시장 ASP 기준이 아님
A7: Gross_Margin_2030 | B7: 0.6 | C7: -8.2601 | D7: -1.1486 | E7: 0.3942 | F7: =D7/B7 | G7: =IF(MAX(C7:E7)>=B7,"PASS","FAIL") | H7: GM60 임계 판매물량 = 209.5 L @ASP 24.93. base 2030 판매 19.8 L = 임계의 9.4%
A8: Payback (년) | B8: 5 | C8: 미도달 | D8: 미도달 | E8: 미도달 | G8: =IF(COUNT(C8:E8)=0,"FAIL",IF(MIN(C8:E8)<=B8,"PASS","FAIL")) | H8: Agent E 의 payback 2030 은 판매 418 L 램프 전제 — V-01 로 무효. 수요 S-curve 대입 시 전 시나리오 미도달
A9: FTO 리스크 | B9: 중 이하 | C9: 중 | D9: 중 | E9: 중 | G9: PASS | H9: Agent F fto_verdict=중. 단 V-06: 회피규격 G'>1.5 kPa 를 E 의 OM-S·G 의 강스템 SKU 가 위반 — 한국 EPFL KR20180038573 등록(→2036)
A11: 종합 판정 — 현 제품정의 | B11: No-Go | C11: 5개 게이트 중 4개 FAIL (SAM·SOM·GM·Payback). 확률가중 E[NPV] = -12,782,884 USD (잔존가치 제외)
A12: 종합 판정 — 대안 스코프 | B12: Conditional-Go | C12: 옵션(d) 라이선싱 + 옵션(e) GMP 원부자재에 한함. 옵션(b)·(c)는 No-Go
A14: DISC-01 재계산 확정 | B14: 옵션(b) GM60 임계 = 판매 289.9 L = 생산 346.7 L (V 289.4 판매 L 와 X 347.3 생산 L 은 동일 값의 단위 차이)

Sheet Evidence_Index
A1: ID | B1: 구분 | C1: 주장 요지 | D1: 값 | E1: 단위 | F1: tier | G1: 신뢰도 | H1: 출처
A2: E-800 | B2: 시장보고서 | C2: 한국 국고채 10년 수익률 (무위험이자율) | D2: 4.30 | E2: % | F2: T2 | G2: 상 | H2: Trading Economics
A3: E-801 | B3: 학술논문 | C3: 한국 총 주식위험프리미엄(ERP) — CAPM 입력 | D3: 4.87 | E3: % | F3: T1 | G3: 상 | H3: Aswath Damodaran / NYU Stern
A4: E-802 | B4: 기업카탈로그 | C4: Corning Matrigel 표준 SKU 354234 제조사 직판 정가 (10 mL) | D4: 302.85 | E4: USD/10 mL | F4: T1 | G4: 상 | H4: Corning Life Sciences (e-catalog)
A5: E-803 | B5: 기업카탈로그 | C5: Corning Matrigel 오가노이드 전용 SKU 356255 제조사 직판 정가 (10 mL) | D5: 447.60 | E5: USD/10 mL | F5: T1 | G5: 상 | H5: Corning Life Sciences (e-catalog)
A6: E-804 | B6: 학술논문 | C6: 산업 베타 (Drugs Biotechnology / Healthcare Products / Chemical Specialty) | D6: levered 1.14 / 0.91 / 0.97, unlevered 1.03 / 0.83 / 0.79, D/E 13.04% / 12.79% / 29.88% | E6: 배·% | F6: T1 | G6: 상 | H6: Aswath Damodaran / NYU Stern
A7: E-805 | B7: 규제문서 | C7: 한국 법인세율 (최고구간 + 지방소득세) | D7: 27.5 | E7: % | F7: T1 | G7: 상 | H7: Chambers and Partners
A8: E-806 | B8: 공시 | C8: LG화학 신용등급 (타인자본비용 스프레드 근거) | D8: Moody's A3 (안정적) / S&P BBB+ | E8: 등급 | F8: T2 | G8: 중 | H8: Cbonds
A9: E-807 | B9: 학술논문 | C9: 산업별 자본비용(WACC) 벤치마크 — 미국, 2026-01 | D9: Drugs(Biotechnology) 8.49 / Drugs(Pharmaceutical) 7.85 / Healthcare Products 7.54 / Chemical(Specialty) 7.25 | E9: % | F9: T1 | G9: 상 | H9: Aswath Damodaran / NYU Stern
A10: E-808 | B10: 공시 | C10: 라이프사이언스 툴 기업의 정상 SG&A·R&D 비율 (Bio-Techne FY2025) | D10: 조정 SG&A 29.0 / R&D 7.8 | E10: % of revenue | F10: T2 | G10: 중 | H10: Bio-Techne Corporation / Yahoo Finance
A11: E-809 | B11: 업계인터뷰 | C11: Field Application Scientist 총보상 (제약·바이오) | D11: 161,181 | E11: USD/년 (median total pay) | F11: T2 | G11: 중 | H11: Glassdoor
A12: E-810 | B12: 시장보고서 | C12: 바이오잉크 시장 규모와 콜라겐 세그먼트 (대안 스코프 옵션 b 입력) | D12: 전체 2025 88.1 M → 2026 99.1 M → 2035 303.2 M, 콜라겐 세그먼트 2025 32.5 M, CAGR 13.2 | E12: M USD / % | F12: T3 | G12: 하 | H12: Global Market Insights (GMI)
... A40: E-838 | B40: 추정 | C40: 규모티어 전환 구간의 총이익률 붕괴 (본 모델의 구조적 발견) | D40: base 2034 판매 65.60 L GM +22.8% → 2035 판매 84.86 L GM −13.2% | E40: % | F40: T3 | G40: 중 | H40: OSVX Agent S
A42: ※ 인용한 선행 에이전트 근거 (신규 생성 아님)
A43: 인용 ID | B43: 생성 Agent | C43: 요지
A44: E-078 | B44: B | C44: nam_ramp base 2026 8% → 2030 25% → 2035 45%
A45: E-102 | B45: C | C45: Corning 356255 오가노이드 SKU 447.60 USD / 10 mL (제조사 직판)
A46: E-125 | B46: C | C46: Yeasen Ceturegel 21.30 USD/mL (중국 로컬 하한)
A47: E-146 | B47: C | C47: 환율 KRW 1,409.94 / CNY 6.7474 / JPY 157.54 per USD
A48: E-152 | B48: C | C48: defined 대체재 7종 20년 누적 인용 점유 1.95%
A49: E-155 | B49: C | C49: Advanced BioMatrix TeloCol-6 11.64 USD/mL
A50: E-161 | B50: C | C50: 정의성 프리미엄 Mann-Whitney p=0.168 — 통계적 유의성 없음
A51: E-228 | B51: D | C51: 콜라겐 I 이 Matrigel 의 1/10 가격에 유전자발현 동등, 그럼에도 미전환
A52: E-231 | B52: D | C52: 2025년 최초 라미닌 무첨가 완전합성 하이드로겔 crypt 형성
A53: E-239 | B53: D | C53: 대체재 검증의 기준점이 거의 항상 Matrigel — 대조군 구매 지속
A54: E-263 | B54: D | C54: 세그먼트별 연간 전환확률 6.0 / 8.3 / 2.7 / 3.2 / 25.0 %
... A70: E-424-R | B70: R | C70: Pichia 재조합 콜라겐 실측 titer 1.05 g/L (E 의 12~16 g/L 대체)
